Workbook
Name Slicer_Error_Type: #N/A
Name Slicer_Lead_Registration_Date: #N/A
Name Slicer_Project_Name: #N/A
Name Slicer_Severity: #N/A
Name Slicer_Telecaller_Name: #N/A

Sheet Cover
A1: Guru Punvaanii – Telecalling Quality Audit
A2: Reusable daily audit workbook • paste CRM data into Raw Data
A4: CONTENTS
A5: Raw Data | B5: Paste or replace the daily CRM export; audit formulas extend with the table.
A6: Executive Dashboard | B6: Management KPIs, reporting period, and headline audit story.
A7: Telecaller Performance | B7: Ranked accuracy scorecard with ratings and severity counts.
A8: Graphical Dashboard | B8: Five visual summaries of accuracy, errors, projects, and severity.
A9: Detailed Error Report | B9: Filterable record-level exceptions with actions and audit status.

Sheet Raw Data
A1: Project Name | B1: Mobile | C1: Telecaller Name | D1: Lead Registration Date | E1: Lead Status | F1: Comments | G1: Next Followup Date | H1: Location | I1: Overdue Days | J1: Status | K1: Analysis Parameter | L1: Customer Requirement | M1: Source | N1: Source Name | O1: Totals | P1: Error Type | Q1: Error Details | R1: Recommended Action | S1: Severity | T1: Audit Status | U1: Error Flag | V1: Accuracy | W1: Telecaller | X1: Accuracy | Z1: Telecaller | AA1: Errors | AC1: Error Type | AD1: Count | AF1: Project | AG1: Errors | AI1: Severity | AJ1: Count
A2: Guru Punvaanii EKA | B2: 7899415022 | C2: Vinutha M1 | D2: 46254 | E2: warm | F2: Seeing for 1200-1500sqft , located at uttarahalli , seeing for self use , said budget is fine , asked me to share details they will check and get back | G2: 46256.458 | I2: -1 | J2: Interested | K2: In Progress | L2: Seeing for 1200-1500sqft , located at uttarahalli , seeing for self use , said budget is fine | M2: Digital Marketing | N2: Meta_StaticAds_Aug2026 | O2: 1 | P2: =IF(RawData[[#This Row],[Mobile]]="","",_xlfn.TEXTJOIN(" | ",TRUE,IF(AND(OR(LOWER(TRIM(RawData[[#This Row],[Lead Status]]))="cold",LOWER(TRIM(RawData[[#This Row],[Lead Status]]))="lost"),OR(ISNUMBER(SEARCH("visit",LOWER(TRIM(RawData[[#This Row],[Comments]])))),ISNUMBER(SEARCH("brochure",LOWER(TRIM(RawData[[#This Row],[Comments]])))),ISNUMBER(SEARCH("pricing",LOWER(TRIM(RawData[[#This Row],[Comments]])))),ISNUMBER(SEARCH("price",LOWER(TRIM(RawData[[#This Row],[Comments]])))),ISNUMBER(SEARCH("budget",LOWER(TRIM(RawData[[#This Row],[Comments]])))))),"Wrong Lead Status",""),IF(AND(LOWER(TRIM(RawData[[#This Row],[Lead Status]]))="cold",OR(LOWER(TRIM(RawData[[#This Row],[Comments]]))="rnr",LOWER(TRIM(RawData[[#This Row],[Comments]]))="busy",LOWER(TRIM(RawData[[#This Row],[Comments]]))="out of network",LOWER(TRIM(RawData[[#This Row],[Comments]]))="outoff network",LOWER(TRIM(RawData[[#This Row],[Comments]]))="voice mail",LOWER(TRIM(RawData[[#This Row],[Comments]]))="voicemail")),"RNR Classification Error",""),IF(AND(LOWER(TRIM(RawData[[#This Row],[Lead Status]]))="warm",OR(LOWER(TRIM(RawData[[#This Row],[Comments]]))="busy",LOWER(TRIM(RawData[[#This Row],[Comments]]))="voice mail",LOWER(TRIM(RawData[[#This Row],[Comments]]))="voicemail",LOWER(TRIM(RawData[[#This Row],[Comments]]))="call back later")),"Warm Status Mismatch",""),IF(AND(LOWER(TRIM(RawData[[#This Row],[Status]]))="rnr",OR(ISNUMBER(SEARCH("requirement",LOWER(RawData[[#This Row],[Comments]]&" "&RawData[[#This Row],[Customer Requirement]]))),ISNUMBER(SEARCH("budget",LOWER(RawData[[#This Row],[Comments]]&" "&RawData[[#This Row],[Customer Requirement]]))),ISNUMBER(SEARCH("location",LOWER(RawData[[#This Row],[Comments]]&" "&RawData[[#This Row],[Customer Requirement]]))),ISNUMBER(SEARCH("purpose",LOWER(RawData[[#This Row],[Comments]]&" "&RawData[[#This Row],[Customer Requirement]]))),ISNUMBER(SEARCH("dimension",LOWER(RawData[[#This Row],[Comments]]&" "&RawData[[#This Row],[Customer Requirement]]))),ISNUMBER(SEARCH("sqft",LOWER(RawData[[#This Row],[Comments]]&" "&RawData[[#This Row],[Customer Requirement]]))))),"CRM Status Mismatch",""),IF(AND(ISNUMBER(RawData[[#This Row],[Next Followup Date]]),RawData[[#This Row],[Next Followup Date]]<NOW(),OR(LOWER(TRIM(RawData[[#This Row],[Lead Status]]))="hot",LOWER(TRIM(RawData[[#This Row],[Lead Status]]))="prospect",LOWER(TRIM(RawData[[#This Row],[Lead Status]]))="warm")),"Follow-up Error",""),IF(AND(LOWER(TRIM(RawData[[#This Row],[Location]]))="anekal",OR(ISNUMBER(SEARCH("ernika",LOWER(RawData[[#This Row],[Project Name]]))),ISNUMBER(SEARCH("enrika",LOWER(RawData[[#This Row],[Project Name]]))),ISNUMBER(SEARCH("exotica",LOWER(RawData[[#This Row],[Project Name]]))),ISNUMBER(SEARCH(" eka",LOWER(RawData[[#This Row],[Project Name]]))))),"Customer Location Not Captured",""))) | Q2: =IF(RawData[[#This Row],[Mobile]]="","",_xlfn.TEXTJOIN(CHAR(10),TRUE,IF(AND(OR(LOWER(TRIM(RawData[[#This Row],[Lead Status]]))="cold",LOWER(TRIM(RawData[[#This Row],[Lead Status]]))="lost"),OR(ISNUMBER(SEARCH("visit",LOWER(TRIM(RawData[[#This Row],[Comments]])))),ISNUMBER(SEARCH("brochure",LOWER(TRIM(RawData[[#This Row],[Comments]])))),ISNUMBER(SEARCH("pricing",LOWER(TRIM(RawData[[#This Row],[Comments]])))),ISNUMBER(SEARCH("price",LOWER(TRIM(RawData[[#This Row],[Comments]])))),ISNUMBER(SEARCH("budget",LOWER(TRIM(RawData[[#This Row],[Comments]])))))),"Engagement intent conflicts with Cold/Lost status",""),IF(AND(LOWER(TRIM(RawData[[#This Row],[Lead Status]]))="cold",OR(LOWER(TRIM(RawData[[#This Row],[Comments]]))="rnr",LOWER(TRIM(RawData[[#This Row],[Comments]]))="busy",LOWER(TRIM(RawData[[#This Row],[Comments]]))="out of network",LOWER(TRIM(RawData[[#This Row],[Comments]]))="outoff network",LOWER(TRIM(RawData[[#This Row],[Comments]]))="voice mail",LOWER(TRIM(RawData[[#This Row],[Comments]]))="voicemail")),"Contact outcome should remain RNR rather than Cold",""),IF(AND(LOWER(TRIM(RawData[[#This Row],[Lead Status]]))="warm",OR(LOWER(TRIM(RawData[[#This Row],[Comments]]))="busy",LOWER(TRIM(RawData[[#This Row],[Comments]]))="voice mail",LOWER(TRIM(RawData[[#This Row],[Comments]]))="voicemail",LOWER(TRIM(RawData[[#This Row],[Comments]]))="call back later")),"Contact-only outcome does not support Warm status",""),IF(AND(LOWER(TRIM(RawData[[#This Row],[Status]]))="rnr",OR(ISNUMBER(SEARCH("requirement",LOWER(RawData[[#This Row],[Comments]]&" "&RawData[[#This Row],[Customer Requirement]]))),ISNUMBER(SEARCH("budget",LOWER(RawData[[#This Row],[Comments]]&" "&RawData[[#This Row],[Customer Requirement]]))),ISNUMBER(SEARCH("location",LOWER(RawData[[#This Row],[Comments]]&" "&RawData[[#This Row],[Customer Requirement]]))),ISNUMBER(SEARCH("purpose",LOWER(RawData[[#This Row],[Comments]]&" "&RawData[[#This Row],[Customer Requirement]]))),ISNUMBER(SEARCH("dimension",LOWER(RawData[[#This Row],[Comments]]&" "&RawData[[#This Row],[Customer Requirement]]))),ISNUMBER(SEARCH("sqft",LOWER(RawData[[#This Row],[Comments]]&" "&RawData[[#This Row],[Customer Requirement]]))))),"Requirements were captured while CRM status remains RNR",""),IF(AND(ISNUMBER(RawData[[#This Row],[Next Followup Date]]),RawData[[#This Row],[Next Followup Date]]<NOW(),OR(LOWER(TRIM(RawData[[#This Row],[Lead Status]]))="hot",LOWER(TRIM(RawData[[#This Row],[Lead Status]]))="prospect",LOWER(TRIM(RawData[[#This Row],[Lead Status]]))="warm")),"Follow-up date/time has passed for an active lead",""),IF(AND(LOWER(TRIM(RawData[[#This Row],[Location]]))="anekal",OR(ISNUMBER(SEARCH("ernika",LOWER(RawData[[#This Row],[Project Name]]))),ISNUMBER(SEARCH("enrika",LOWER(RawData[[#This Row],[Project Name]]))),ISNUMBER(SEARCH("exotica",LOWER(RawData[[#This Row],[Project Name]]))),ISNUMBER(SEARCH(" eka",LOWER(RawData[[#This Row],[Project Name]]))))),"Anekal is the project default; customer location was not captured",""))) | R2: =IF(RawData[[#This Row],[Mobile]]="","",_xlfn.TEXTJOIN(CHAR(10),TRUE,IF(AND(OR(LOWER(TRIM(RawData[[#This Row],[Lead Status]]))="cold",LOWER(TRIM(RawData[[#This Row],[Lead Status]]))="lost"),OR(ISNUMBER(SEARCH("visit",LOWER(TRIM(RawData[[#This Row],[Comments]])))),ISNUMBER(SEARCH("brochure",LOWER(TRIM(RawData[[#This Row],[Comments]])))),ISNUMBER(SEARCH("pricing",LOWER(TRIM(RawData[[#This Row],[Comments]])))),ISNUMBER(SEARCH("price",LOWER(TRIM(RawData[[#This Row],[Comments]])))),ISNUMBER(SEARCH("budget",LOWER(TRIM(RawData[[#This Row],[Comments]])))))),"Reclassify lead and schedule a documented follow-up",""),IF(AND(LOWER(TRIM(RawData[[#This Row],[Lead Status]]))="cold",OR(LOWER(TRIM(RawData[[#This Row],[Comments]]))="rnr",LOWER(TRIM(RawData[[#This Row],[Comments]]))="busy",LOWER(TRIM(RawData[[#This Row],[Comments]]))="out of network",LOWER(TRIM(RawData[[#This Row],[Comments]]))="outoff network",LOWER(TRIM(RawData[[#This Row],[Comments]]))="voice mail",LOWER(TRIM(RawData[[#This Row],[Comments]]))="voicemail")),"Change lead classification to RNR and retry contact",""),IF(AND(LOWER(TRIM(RawData[[#This Row],[Lead Status]]))="warm",OR(LOWER(TRIM(RawData[[#This Row],[Comments]]))="busy",LOWER(TRIM(RawData[[#This Row],[Comments]]))="voice mail",LOWER(TRIM(RawData[[#This Row],[Comments]]))="voicemail",LOWER(TRIM(RawData[[#This Row],[Comments]]))="call back later")),"Validate engagement before retaining Warm status",""),IF(AND(LOWER(TRIM(RawData[[#This Row],[Status]]))="rnr",OR(ISNUMBER(SEARCH("requirement",LOWER(RawData[[#This Row],[Comments]]&" "&RawData[[#This Row],[Customer Requirement]]))),ISNUMBER(SEARCH("budget",LOWER(RawData[[#This Row],[Comments]]&" "&RawData[[#This Row],[Customer Requirement]]))),ISNUMBER(SEARCH("location",LOWER(RawData[[#This Row],[Comments]]&" "&RawData[[#This Row],[Customer Requirement]]))),ISNUMBER(SEARCH("purpose",LOWER(RawData[[#This Row],[Comments]]&" "&RawData[[#This Row],[Customer Requirement]]))),ISNUMBER(SEARCH("dimension",LOWER(RawData[[#This Row],[Comments]]&" "&RawData[[#This Row],[Customer Requirement]]))),ISNUMBER(SEARCH("sqft",LOWER(RawData[[#This Row],[Comments]]&" "&RawData[[#This Row],[Customer Requirement]]))))),"Update CRM status to reflect the collected requirement",""),IF(AND(ISNUMBER(RawData[[#This Row],[Next Followup Date]]),RawData[[#This Row],[Next Followup Date]]<NOW(),OR(LOWER(TRIM(RawData[[#This Row],[Lead Status]]))="hot",LOWER(TRIM(RawData[[#This Row],[Lead Status]]))="prospect",LOWER(TRIM(RawData[[#This Row],[Lead Status]]))="warm")),"Contact immediately and set the next follow-up",""),IF(AND(LOWER(TRIM(RawData[[#This Row],[Location]]))="anekal",OR(ISNUMBER(SEARCH("ernika",LOWER(RawData[[#This Row],[Project Name]]))),ISNUMBER(SEARCH("enrika",LOWER(RawData[[#This Row],[Project Name]]))),ISNUMBER(SEARCH("exotica",LOWER(RawData[[#This Row],[Project Name]]))),ISNUMBER(SEARCH(" eka",LOWER(RawData[[#This Row],[Project Name]]))))),"Contact the customer and record their actual location",""))) | S2: =IF(RawData[[#This Row],[Error Flag]]=0,"",IF(OR(ISNUMBER(SEARCH("Wrong Lead Status",RawData[[#This Row],[Error Type]])),ISNUMBER(SEARCH("RNR Classification Error",RawData[[#This Row],[Error Type]])),ISNUMBER(SEARCH("Follow-up Error",RawData[[#This Row],[Error Type]]))),"Critical","Medium")) | T2: =IF(RawData[[#This Row],[Error Flag]]=0,"Pass","Action Required ("&RawData[[#This Row],[Error Flag]]&IF(RawData[[#This Row],[Error Flag]]=1," error)"," errors)")) -> Pass | U2: =IF(RawData[[#This Row],[Mobile]]="",0,--(AND(OR(LOWER(TRIM(RawData[[#This Row],[Lead Status]]))="cold",LOWER(TRIM(RawData[[#This Row],[Lead Status]]))="lost"),OR(ISNUMBER(SEARCH("visit",LOWER(TRIM(RawData[[#This Row],[Comments]])))),ISNUMBER(SEARCH("brochure",LOWER(TRIM(RawData[[#This Row],[Comments]])))),ISNUMBER(SEARCH("pricing",LOWER(TRIM(RawData[[#This Row],[Comments]])))),ISNUMBER(SEARCH("price",LOWER(TRIM(RawData[[#This Row],[Comments]])))),ISNUMBER(SEARCH("budget",LOWER(TRIM(RawData[[#This Row],[Comments]])))))))+--(AND(LOWER(TRIM(RawData[[#This Row],[Lead Status]]))="cold",OR(LOWER(TRIM(RawData[[#This Row],[Comments]]))="rnr",LOWER(TRIM(RawData[[#This Row],[Comments]]))="busy",LOWER(TRIM(RawData[[#This Row],[Comments]]))="out of network",LOWER(TRIM(RawData[[#This Row],[Comments]]))="outoff network",LOWER(TRIM(RawData[[#This Row],[Comments]]))="voice mail",LOWER(TRIM(RawData[[#This Row],[Comments]]))="voicemail")))+--(AND(LOWER(TRIM(RawData[[#This Row],[Lead Status]]))="warm",OR(LOWER(TRIM(RawData[[#This Row],[Comments]]))="busy",LOWER(TRIM(RawData[[#This Row],[Comments]]))="voice mail",LOWER(TRIM(RawData[[#This Row],[Comments]]))="voicemail",LOWER(TRIM(RawData[[#This Row],[Comments]]))="call back later")))+--(AND(LOWER(TRIM(RawData[[#This Row],[Status]]))="rnr",OR(ISNUMBER(SEARCH("requirement",LOWER(RawData[[#This Row],[Comments]]&" "&RawData[[#This Row],[Customer Requirement]]))),ISNUMBER(SEARCH("budget",LOWER(RawData[[#This Row],[Comments]]&" "&RawData[[#This Row],[Customer Requirement]]))),ISNUMBER(SEARCH("location",LOWER(RawData[[#This Row],[Comments]]&" "&RawData[[#This Row],[Customer Requirement]]))),ISNUMBER(SEARCH("purpose",LOWER(RawData[[#This Row],[Comments]]&" "&RawData[[#This Row],[Customer Requirement]]))),ISNUMBER(SEARCH("dimension",LOWER(RawData[[#This Row],[Comments]]&" "&RawData[[#This Row],[Customer Requirement]]))),ISNUMBER(SEARCH("sqft",LOWER(RawData[[#This Row],[Comments]]&" "&RawData[[#This Row],[Customer Requirement]]))))))+--(AND(ISNUMBER(RawData[[#This Row],[Next Followup Date]]),RawData[[#This Row],[Next Followup Date]]<NOW(),OR(LOWER(TRIM(RawData[[#This Row],[Lead Status]]))="hot",LOWER(TRIM(RawData[[#This Row],[Lead Status]]))="prospect",LOWER(TRIM(RawData[[#This Row],[Lead Status]]))="warm")))+--(AND(LOWER(TRIM(RawData[[#This Row],[Location]]))="anekal",OR(ISNUMBER(SEARCH("ernika",LOWER(RawData[[#This Row],[Project Name]]))),ISNUMBER(SEARCH("enrika",LOWER(RawData[[#This Row],[Project Name]]))),ISNUMBER(SEARCH("exotica",LOWER(RawData[[#This Row],[Project Name]]))),ISNUMBER(SEARCH(" eka",LOWER(RawData[[#This Row],[Project Name]]))))))) -> 0 | W2: ='Telecaller Performance'!A6 -> Prathima Hegde | X2: {=IF(W2="",NA(),_xlfn.LET(_xlpm.v,SUBTOTAL(103,OFFSET(RawData[Mobile],ROW(RawData[Mobile])-MIN(ROW(RawData[Mobile])),0,1)),_xlpm.z,SUMPRODUCT(_xlpm.v,--(RawData[Telecaller Name]=W2)),IF(_xlpm.z=0,NA(),MAX(0,1-SUMPRODUCT(_xlpm.v,--(RawData[Telecaller Name]=W2),RawData[Error Flag])/_xlpm.z))))} -> 1 | Z2: ='Telecaller Performance'!A6 -> Prathima Hegde | AA2: {=IF(Z2="",NA(),_xlfn.LET(_xlpm.v,SUBTOTAL(103,OFFSET(RawData[Mobile],ROW(RawData[Mobile])-MIN(ROW(RawData[Mobile])),0,1)),_xlpm.z,SUMPRODUCT(_xlpm.v,--(RawData[Telecaller Name]=Z2)),IF(_xlpm.z=0,NA(),SUMPRODUCT(_xlpm.v,--(RawData[Telecaller Name]=Z2),RawData[Error Flag]))))} -> 0 | AC2: Wrong Lead Status | AD2: {=_xlfn.LET(_xlpm.v,SUBTOTAL(103,OFFSET(RawData[Mobile],ROW(RawData[Mobile])-MIN(ROW(RawData[Mobile])),0,1)),SUMPRODUCT(_xlpm.v,--ISNUMBER(SEARCH(AC2,RawData[Error Type]))))} -> 3 | AF2: {=IFERROR(INDEX(_xlfn._xlws.SORT(_xlfn.UNIQUE(_xlfn._xlws.FILTER(RawData[Project Name],RawData[Project Name]<>""))),ROWS(AF$2:AF2)),"")} -> Guru Punvaanii EKA | AG2: {=IF(AF2="",NA(),_xlfn.LET(_xlpm.v,SUBTOTAL(103,OFFSET(RawData[Mobile],ROW(RawData[Mobile])-MIN(ROW(RawData[Mobile])),0,1)),_xlpm.z,SUMPRODUCT(_xlpm.v,--(RawData[Project Name]=AF2)),IF(_xlpm.z=0,NA(),SUMPRODUCT(_xlpm.v,--(RawData[Project Name]=AF2),RawData[Error Flag]))))} -> 1 | AI2: Critical | AJ2: {=_xlfn.LET(_xlpm.v,SUBTOTAL(103,OFFSET(RawData[Mobile],ROW(RawData[Mobile])-MIN(ROW(RawData[Mobile])),0,1)),SUMPRODUCT(_xlpm.v,--ISNUMBER(SEARCH("Wrong Lead Status",RawData[Error Type])))+SUMPRODUCT(_xlpm.v,--ISNUMBER(SEARCH("RNR Classification Error",RawData[Error Type])))+SUMPRODUCT(_xlpm.v,--ISNUMBER(SEARCH("Follow-up Error",RawData[Error Type]))))} -> 8
A3: Guru Punvaanii EKA | B3: 8861583888 | C3: Vinutha M1 | D3: 46253 | E3: warm | F3: Txted in whatsapp asked me to share details | G3: 46256.495 | H3: Anekal | I3: -1 | J3: Interested | K3: RNR | L3: . | M3: Digital Marketing | N3: SEO | O3: 1 | P3: =IF(RawData[[#This Row],[Mobile]]="","",_xlfn.TEXTJOIN(" | ",TRUE,IF(AND(OR(LOWER(TRIM(RawData[[#This Row],[Lead Status]]))="cold",LOWER(TRIM(RawData[[#This Row],[Lead Status]]))="lost"),OR(ISNUMBER(SEARCH("visit",LOWER(TRIM(RawData[[#This Row],[Comments]])))),ISNUMBER(SEARCH("brochure",LOWER(TRIM(RawData[[#This Row],[Comments]])))),ISNUMBER(SEARCH("pricing",LOWER(TRIM(RawData[[#This Row],[Comments]])))),ISNUMBER(SEARCH("price",LOWER(TRIM(RawData[[#This Row],[Comments]])))),ISNUMBER(SEARCH("budget",LOWER(TRIM(RawData[[#This Row],[Comments]])))))),"Wrong Lead Status",""),IF(AND(LOWER(TRIM(RawData[[#This Row],[Lead Status]]))="cold",OR(LOWER(TRIM(RawData[[#This Row],[Comments]]))="rnr",LOWER(TRIM(RawData[[#This Row],[Comments]]))="busy",LOWER(TRIM(RawData[[#This Row],[Comments]]))="out of network",LOWER(TRIM(RawData[[#This Row],[Comments]]))="outoff network",LOWER(TRIM(RawData[[#This Row],[Comments]]))="voice mail",LOWER(TRIM(RawData[[#This Row],[Comments]]))="voicemail")),"RNR Classification Error",""),IF(AND(LOWER(TRIM(RawData[[#This Row],[Lead Status]]))="warm",OR(LOWER(TRIM(RawData[[#This Row],[Comments]]))="busy",LOWER(TRIM(RawData[[#This Row],[Comments]]))="voice mail",LOWER(TRIM(RawData[[#This Row],[Comments]]))="voicemail",LOWER(TRIM(RawData[[#This Row],[Comments]]))="call back later")),"Warm Status Mismatch",""),IF(AND(LOWER(TRIM(RawData[[#This Row],[Status]]))="rnr",OR(ISNUMBER(SEARCH("requirement",LOWER(RawData[[#This Row],[Comments]]&" "&RawData[[#This Row],[Customer Requirement]]))),ISNUMBER(SEARCH("budget",LOWER(RawData[[#This Row],[Comments]]&" "&RawData[[#This Row],[Customer Requirement]]))),ISNUMBER(SEARCH("location",LOWER(RawData[[#This Row],[Comments]]&" "&RawData[[#This Row],[Customer Requirement]]))),ISNUMBER(SEARCH("purpose",LOWER(RawData[[#This Row],[Comments]]&" "&RawData[[#This Row],[Customer Requirement]]))),ISNUMBER(SEARCH("dimension",LOWER(RawData[[#This Row],[Comments]]&" "&RawData[[#This Row],[Customer Requirement]]))),ISNUMBER(SEARCH("sqft",LOWER(RawData[[#This Row],[Comments]]&" "&RawData[[#This Row],[Customer Requirement]]))))),"CRM Status Mismatch",""),IF(AND(ISNUMBER(RawData[[#This Row],[Next Followup Date]]),RawData[[#This Row],[Next Followup Date]]<NOW(),OR(LOWER(TRIM(RawData[[#This Row],[Lead Status]]))="hot",LOWER(TRIM(RawData[[#This Row],[Lead Status]]))="prospect",LOWER(TRIM(RawData[[#This Row],[Lead Status]]))="warm")),"Follow-up Error",""),IF(AND(LOWER(TRIM(RawData[[#This Row],[Location]]))="anekal",OR(ISNUMBER(SEARCH("ernika",LOWER(RawData[[#This Row],[Project Name]]))),ISNUMBER(SEARCH("enrika",LOWER(RawData[[#This Row],[Project Name]]))),ISNUMBER(SEARCH("exotica",LOWER(RawData[[#This Row],[Project Name]]))),ISNUMBER(SEARCH(" eka",LOWER(RawData[[#This Row],[Project Name]]))))),"Customer Location Not Captured",""))) -> Customer Location Not Captured | Q3: =IF(RawData[[#This Row],[Mobile]]="","",_xlfn.TEXTJOIN(CHAR(10),TRUE,IF(AND(OR(LOWER(TRIM(RawData[[#This Row],[Lead Status]]))="cold",LOWER(TRIM(RawData[[#This Row],[Lead Status]]))="lost"),OR(ISNUMBER(SEARCH("visit",LOWER(TRIM(RawData[[#This Row],[Comments]])))),ISNUMBER(SEARCH("brochure",LOWER(TRIM(RawData[[#This Row],[Comments]])))),ISNUMBER(SEARCH("pricing",LOWER(TRIM(RawData[[#This Row],[Comments]])))),ISNUMBER(SEARCH("price",LOWER(TRIM(RawData[[#This Row],[Comments]])))),ISNUMBER(SEARCH("budget",LOWER(TRIM(RawData[[#This Row],[Comments]])))))),"Engagement intent conflicts with Cold/Lost status",""),IF(AND(LOWER(TRIM(RawData[[#This Row],[Lead Status]]))="cold",OR(LOWER(TRIM(RawData[[#This Row],[Comments]]))="rnr",LOWER(TRIM(RawData[[#This Row],[Comments]]))="busy",LOWER(TRIM(RawData[[#This Row],[Comments]]))="out of network",LOWER(TRIM(RawData[[#This Row],[Comments]]))="outoff network",LOWER(TRIM(RawData[[#This Row],[Comments]]))="voice mail",LOWER(TRIM(RawData[[#This Row],[Comments]]))="voicemail")),"Contact outcome should remain RNR rather than Cold",""),IF(AND(LOWER(TRIM(RawData[[#This Row],[Lead Status]]))="warm",OR(LOWER(TRIM(RawData[[#This Row],[Comments]]))="busy",LOWER(TRIM(RawData[[#This Row],[Comments]]))="voice mail",LOWER(TRIM(RawData[[#This Row],[Comments]]))="voicemail",LOWER(TRIM(RawData[[#This Row],[Comments]]))="call back later")),"Contact-only outcome does not support Warm status",""),IF(AND(LOWER(TRIM(RawData[[#This Row],[Status]]))="rnr",OR(ISNUMBER(SEARCH("requirement",LOWER(RawData[[#This Row],[Comments]]&" "&RawData[[#This Row],[Customer Requirement]]))),ISNUMBER(SEARCH("budget",LOWER(RawData[[#This Row],[Comments]]&" "&RawData[[#This Row],[Customer Requirement]]))),ISNUMBER(SEARCH("location",LOWER(RawData[[#This Row],[Comments]]&" "&RawData[[#This Row],[Customer Requirement]]))),ISNUMBER(SEARCH("purpose",LOWER(RawData[[#This Row],[Comments]]&" "&RawData[[#This Row],[Customer Requirement]]))),ISNUMBER(SEARCH("dimension",LOWER(RawData[[#This Row],[Comments]]&" "&RawData[[#This Row],[Customer Requirement]]))),ISNUMBER(SEARCH("sqft",LOWER(RawData[[#This Row],[Comments]]&" "&RawData[[#This Row],[Customer Requirement]]))))),"Requirements were captured while CRM status remains RNR",""),IF(AND(ISNUMBER(RawData[[#This Row],[Next Followup Date]]),RawData[[#This Row],[Next Followup Date]]<NOW(),OR(LOWER(TRIM(RawData[[#This Row],[Lead Status]]))="hot",LOWER(TRIM(RawData[[#This Row],[Lead Status]]))="prospect",LOWER(TRIM(RawData[[#This Row],[Lead Status]]))="warm")),"Follow-up date/time has passed for an active lead",""),IF(AND(LOWER(TRIM(RawData[[#This Row],[Location]]))="anekal",OR(ISNUMBER(SEARCH("ernika",LOWER(RawData[[#This Row],[Project Name]]))),ISNUMBER(SEARCH("enrika",LOWER(RawData[[#This Row],[Project Name]]))),ISNUMBER(SEARCH("exotica",LOWER(RawData[[#This Row],[Project Name]]))),ISNUMBER(SEARCH(" eka",LOWER(RawData[[#This Row],[Project Name]]))))),"Anekal is the project default; customer location was not captured",""))) -> Anekal is the project default; customer location was not captured | R3: =IF(RawData[[#This Row],[Mobile]]="","",_xlfn.TEXTJOIN(CHAR(10),TRUE,IF(AND(OR(LOWER(TRIM(RawData[[#This Row],[Lead Status]]))="cold",LOWER(TRIM(RawData[[#This Row],[Lead Status]]))="lost"),OR(ISNUMBER(SEARCH("visit",LOWER(TRIM(RawData[[#This Row],[Comments]])))),ISNUMBER(SEARCH("brochure",LOWER(TRIM(RawData[[#This Row],[Comments]])))),ISNUMBER(SEARCH("pricing",LOWER(TRIM(RawData[[#This Row],[Comments]])))),ISNUMBER(SEARCH("price",LOWER(TRIM(RawData[[#This Row],[Comments]])))),ISNUMBER(SEARCH("budget",LOWER(TRIM(RawData[[#This Row],[Comments]])))))),"Reclassify lead and schedule a documented follow-up",""),IF(AND(LOWER(TRIM(RawData[[#This Row],[Lead Status]]))="cold",OR(LOWER(TRIM(RawData[[#This Row],[Comments]]))="rnr",LOWER(TRIM(RawData[[#This Row],[Comments]]))="busy",LOWER(TRIM(RawData[[#This Row],[Comments]]))="out of network",LOWER(TRIM(RawData[[#This Row],[Comments]]))="outoff network",LOWER(TRIM(RawData[[#This Row],[Comments]]))="voice mail",LOWER(TRIM(RawData[[#This Row],[Comments]]))="voicemail")),"Change lead classification to RNR and retry contact",""),IF(AND(LOWER(TRIM(RawData[[#This Row],[Lead Status]]))="warm",OR(LOWER(TRIM(RawData[[#This Row],[Comments]]))="busy",LOWER(TRIM(RawData[[#This Row],[Comments]]))="voice mail",LOWER(TRIM(RawData[[#This Row],[Comments]]))="voicemail",LOWER(TRIM(RawData[[#This Row],[Comments]]))="call back later")),"Validate engagement before retaining Warm status",""),IF(AND(LOWER(TRIM(RawData[[#This Row],[Status]]))="rnr",OR(ISNUMBER(SEARCH("requirement",LOWER(RawData[[#This Row],[Comments]]&" "&RawData[[#This Row],[Customer Requirement]]))),ISNUMBER(SEARCH("budget",LOWER(RawData[[#This Row],[Comments]]&" "&RawData[[#This Row],[Customer Requirement]]))),ISNUMBER(SEARCH("location",LOWER(RawData[[#This Row],[Comments]]&" "&RawData[[#This Row],[Customer Requirement]]))),ISNUMBER(SEARCH("purpose",LOWER(RawData[[#This Row],[Comments]]&" "&RawData[[#This Row],[Customer Requirement]]))),ISNUMBER(SEARCH("dimension",LOWER(RawData[[#This Row],[Comments]]&" "&RawData[[#This Row],[Customer Requirement]]))),ISNUMBER(SEARCH("sqft",LOWER(RawData[[#This Row],[Comments]]&" "&RawData[[#This Row],[Customer Requirement]]))))),"Update CRM status to reflect the collected requirement",""),IF(AND(ISNUMBER(RawData[[#This Row],[Next Followup Date]]),RawData[[#This Row],[Next Followup Date]]<NOW(),OR(LOWER(TRIM(RawData[[#This Row],[Lead Status]]))="hot",LOWER(TRIM(RawData[[#This Row],[Lead Status]]))="prospect",LOWER(TRIM(RawData[[#This Row],[Lead Status]]))="warm")),"Contact immediately and set the next follow-up",""),IF(AND(LOWER(TRIM(RawData[[#This Row],[Location]]))="anekal",OR(ISNUMBER(SEARCH("ernika",LOWER(RawData[[#This Row],[Project Name]]))),ISNUMBER(SEARCH("enrika",LOWER(RawData[[#This Row],[Project Name]]))),ISNUMBER(SEARCH("exotica",LOWER(RawData[[#This Row],[Project Name]]))),ISNUMBER(SEARCH(" eka",LOWER(RawData[[#This Row],[Project Name]]))))),"Contact the customer and record their actual location",""))) -> Contact the customer and record their actual location | S3: =IF(RawData[[#This Row],[Error Flag]]=0,"",IF(OR(ISNUMBER(SEARCH("Wrong Lead Status",RawData[[#This Row],[Error Type]])),ISNUMBER(SEARCH("RNR Classification Error",RawData[[#This Row],[Error Type]])),ISNUMBER(SEARCH("Follow-up Error",RawData[[#This Row],[Error Type]]))),"Critical","Medium")) -> Medium | T3: =IF(RawData[[#This Row],[Error Flag]]=0,"Pass","Action Required ("&RawData[[#This Row],[Error Flag]]&IF(RawData[[#This Row],[Error Flag]]=1," error)"," errors)")) -> Action Required (1 error) | U3: =IF(RawData[[#This Row],[Mobile]]="",0,--(AND(OR(LOWER(TRIM(RawData[[#This Row],[Lead Status]]))="cold",LOWER(TRIM(RawData[[#This Row],[Lead Status]]))="lost"),OR(ISNUMBER(SEARCH("visit",LOWER(TRIM(RawData[[#This Row],[Comments]])))),ISNUMBER(SEARCH("brochure",LOWER(TRIM(RawData[[#This Row],[Comments]])))),ISNUMBER(SEARCH("pricing",LOWER(TRIM(RawData[[#This Row],[Comments]])))),ISNUMBER(SEARCH("price",LOWER(TRIM(RawData[[#This Row],[Comments]])))),ISNUMBER(SEARCH("budget",LOWER(TRIM(RawData[[#This Row],[Comments]])))))))+--(AND(LOWER(TRIM(RawData[[#This Row],[Lead Status]]))="cold",OR(LOWER(TRIM(RawData[[#This Row],[Comments]]))="rnr",LOWER(TRIM(RawData[[#This Row],[Comments]]))="busy",LOWER(TRIM(RawData[[#This Row],[Comments]]))="out of network",LOWER(TRIM(RawData[[#This Row],[Comments]]))="outoff network",LOWER(TRIM(RawData[[#This Row],[Comments]]))="voice mail",LOWER(TRIM(RawData[[#This Row],[Comments]]))="voicemail")))+--(AND(LOWER(TRIM(RawData[[#This Row],[Lead Status]]))="warm",OR(LOWER(TRIM(RawData[[#This Row],[Comments]]))="busy",LOWER(TRIM(RawData[[#This Row],[Comments]]))="voice mail",LOWER(TRIM(RawData[[#This Row],[Comments]]))="voicemail",LOWER(TRIM(RawData[[#This Row],[Comments]]))="call back later")))+--(AND(LOWER(TRIM(RawData[[#This Row],[Status]]))="rnr",OR(ISNUMBER(SEARCH("requirement",LOWER(RawData[[#This Row],[Comments]]&" "&RawData[[#This Row],[Customer Requirement]]))),ISNUMBER(SEARCH("budget",LOWER(RawData[[#This Row],[Comments]]&" "&RawData[[#This Row],[Customer Requirement]]))),ISNUMBER(SEARCH("location",LOWER(RawData[[#This Row],[Comments]]&" "&RawData[[#This Row],[Customer Requirement]]))),ISNUMBER(SEARCH("purpose",LOWER(RawData[[#This Row],[Comments]]&" "&RawData[[#This Row],[Customer Requirement]]))),ISNUMBER(SEARCH("dimension",LOWER(RawData[[#This Row],[Comments]]&" "&RawData[[#This Row],[Customer Requirement]]))),ISNUMBER(SEARCH("sqft",LOWER(RawData[[#This Row],[Comments]]&" "&RawData[[#This Row],[Customer Requirement]]))))))+--(AND(ISNUMBER(RawData[[#This Row],[Next Followup Date]]),RawData[[#This Row],[Next Followup Date]]<NOW(),OR(LOWER(TRIM(RawData[[#This Row],[Lead Status]]))="hot",LOWER(TRIM(RawData[[#This Row],[Lead Status]]))="prospect",LOWER(TRIM(RawData[[#This Row],[Lead Status]]))="warm")))+--(AND(LOWER(TRIM(RawData[[#This Row],[Location]]))="anekal",OR(ISNUMBER(SEARCH("ernika",LOWER(RawData[[#This Row],[Project Name]]))),ISNUMBER(SEARCH("enrika",LOWER(RawData[[#This Row],[Project Name]]))),ISNUMBER(SEARCH("exotica",LOWER(RawData[[#This Row],[Project Name]]))),ISNUMBER(SEARCH(" eka",LOWER(RawData[[#This Row],[Project Name]]))))))) -> 1 | W3: ='Telecaller Performance'!A7 -> Vinutha M1 | X3: {=IF(W3="",NA(),_xlfn.LET(_xlpm.v,SUBTOTAL(103,OFFSET(RawData[Mobile],ROW(RawData[Mobile])-MIN(ROW(RawData[Mobile])),0,1)),_xlpm.z,SUMPRODUCT(_xlpm.v,--(RawData[Telecaller Name]=W3)),IF(_xlpm.z=0,NA(),MAX(0,1-SUMPRODUCT(_xlpm.v,--(RawData[Telecaller Name]=W3),RawData[Error Flag])/_xlpm.z))))} -> 0.21428571 | Z3: ='Telecaller Performance'!A7 -> Vinutha M1 | AA3: {=IF(Z3="",NA(),_xlfn.LET(_xlpm.v,SUBTOTAL(103,OFFSET(RawData[Mobile],ROW(RawData[Mobile])-MIN(ROW(RawData[Mobile])),0,1)),_xlpm.z,SUMPRODUCT(_xlpm.v,--(RawData[Telecaller Name]=Z3)),IF(_xlpm.z=0,NA(),SUMPRODUCT(_xlpm.v,--(RawData[Telecaller Name]=Z3),RawData[Error Flag]))))} -> 22 | AC3: Cold Status Mismatch | AD3: {=_xlfn.LET(_xlpm.v,SUBTOTAL(103,OFFSET(RawData[Mobile],ROW(RawData[Mobile])-MIN(ROW(RawData[Mobile])),0,1)),SUMPRODUCT(_xlpm.v,--ISNUMBER(SEARCH(AC3,RawData[Error Type]))))} -> 0 | AF3: {=IFERROR(INDEX(_xlfn._xlws.SORT(_xlfn.UNIQUE(_xlfn._xlws.FILTER(RawData[Project Name],RawData[Project Name]<>""))),ROWS(AF$2:AF3)),"")} -> Guru Punvaanii Elegance | AG3: {=IF(AF3="",NA(),_xlfn.LET(_xlpm.v,SUBTOTAL(103,OFFSET(RawData[Mobile],ROW(RawData[Mobile])-MIN(ROW(RawData[Mobile])),0,1)),_xlpm.z,SUMPRODUCT(_xlpm.v,--(RawData[Project Name]=AF3)),IF(_xlpm.z=0,NA(),SUMPRODUCT(_xlpm.v,--(RawData[Project Name]=AF3),RawData[Error Flag]))))} -> 1 | AI3: Medium | AJ3: {=_xlfn.LET(_xlpm.v,SUBTOTAL(103,OFFSET(RawData[Mobile],ROW(RawData[Mobile])-MIN(ROW(RawData[Mobile])),0,1)),SUMPRODUCT(_xlpm.v,--ISNUMBER(SEARCH("Warm Status Mismatch",RawData[Error Type])))+SUMPRODUCT(_xlpm.v,--ISNUMBER(SEARCH("CRM Status Mismatch",RawData[Error Type])))+SUMPRODUCT(_xlpm.v,--ISNUMBER(SEARCH("Customer Location Not Captured",RawData[Error Type]))))} -> 19
A4: Guru Punvaanii EKA | B4: 9513809427 | C4: Vinutha M1 | D4: 46253 | E4: warm | F4: Rnr | G4: 46256.465 | I4: -1 | J4: Interested | K4: RNR | L4: .. | M4: Digital Marketing | N4: Meta_StaticAds_Aug2026 | O4: 1 | P4: =IF(RawData[[#This Row],[Mobile]]="","",_xlfn.TEXTJOIN(" | ",TRUE,IF(AND(OR(LOWER(TRIM(RawData[[#This Row],[Lead Status]]))="cold",LOWER(TRIM(RawData[[#This Row],[Lead Status]]))="lost"),OR(ISNUMBER(SEARCH("visit",LOWER(TRIM(RawData[[#This Row],[Comments]])))),ISNUMBER(SEARCH("brochure",LOWER(TRIM(RawData[[#This Row],[Comments]])))),ISNUMBER(SEARCH("pricing",LOWER(TRIM(RawData[[#This Row],[Comments]])))),ISNUMBER(SEARCH("price",LOWER(TRIM(RawData[[#This Row],[Comments]])))),ISNUMBER(SEARCH("budget",LOWER(TRIM(RawData[[#This Row],[Comments]])))))),"Wrong Lead Status",""),IF(AND(LOWER(TRIM(RawData[[#This Row],[Lead Status]]))="cold",OR(LOWER(TRIM(RawData[[#This Row],[Comments]]))="rnr",LOWER(TRIM(RawData[[#This Row],[Comments]]))="busy",LOWER(TRIM(RawData[[#This Row],[Comments]]))="out of network",LOWER(TRIM(RawData[[#This Row],[Comments]]))="outoff network",LOWER(TRIM(RawData[[#This Row],[Comments]]))="voice mail",LOWER(TRIM(RawData[[#This Row],[Comments]]))="voicemail")),"RNR Classification Error",""),IF(AND(LOWER(TRIM(RawData[[#This Row],[Lead Status]]))="warm",OR(LOWER(TRIM(RawData[[#This Row],[Comments]]))="busy",LOWER(TRIM(RawData[[#This Row],[Comments]]))="voice mail",LOWER(TRIM(RawData[[#This Row],[Comments]]))="voicemail",LOWER(TRIM(RawData[[#This Row],[Comments]]))="call back later")),"Warm Status Mismatch",""),IF(AND(LOWER(TRIM(RawData[[#This Row],[Status]]))="rnr",OR(ISNUMBER(SEARCH("requirement",LOWER(RawData[[#This Row],[Comments]]&" "&RawData[[#This Row],[Customer Requirement]]))),ISNUMBER(SEARCH("budget",LOWER(RawData[[#This Row],[Comments]]&" "&RawData[[#This Row],[Customer Requirement]]))),ISNUMBER(SEARCH("location",LOWER(RawData[[#This Row],[Comments]]&" "&RawData[[#This Row],[Customer Requirement]]))),ISNUMBER(SEARCH("purpose",LOWER(RawData[[#This Row],[Comments]]&" "&RawData[[#This Row],[Customer Requirement]]))),ISNUMBER(SEARCH("dimension",LOWER(RawData[[#This Row],[Comments]]&" "&RawData[[#This Row],[Customer Requirement]]))),ISNUMBER(SEARCH("sqft",LOWER(RawData[[#This Row],[Comments]]&" "&RawData[[#This Row],[Customer Requirement]]))))),"CRM Status Mismatch",""),IF(AND(ISNUMBER(RawData[[#This Row],[Next Followup Date]]),RawData[[#This Row],[Next Followup Date]]<NOW(),OR(LOWER(TRIM(RawData[[#This Row],[Lead Status]]))="hot",LOWER(TRIM(RawData[[#This Row],[Lead Status]]))="prospect",LOWER(TRIM(RawData[[#This Row],[Lead Status]]))="warm")),"Follow-up Error",""),IF(AND(LOWER(TRIM(RawData[[#This Row],[Location]]))="anekal",OR(ISNUMBER(SEARCH("ernika",LOWER(RawData[[#This Row],[Project Name]]))),ISNUMBER(SEARCH("enrika",LOWER(RawData[[#This Row],[Project Name]]))),ISNUMBER(SEARCH("exotica",LOWER(RawData[[#This Row],[Project Name]]))),ISNUMBER(SEARCH(" eka",LOWER(RawData[[#This Row],[Project Name]]))))),"Customer Location Not Captured",""))) | Q4: =IF(RawData[[#This Row],[Mobile]]="","",_xlfn.TEXTJOIN(CHAR(10),TRUE,IF(AND(OR(LOWER(TRIM(RawData[[#This Row],[Lead Status]]))="cold",LOWER(TRIM(RawData[[#This Row],[Lead Status]]))="lost"),OR(ISNUMBER(SEARCH("visit",LOWER(TRIM(RawData[[#This Row],[Comments]])))),ISNUMBER(SEARCH("brochure",LOWER(TRIM(RawData[[#This Row],[Comments]])))),ISNUMBER(SEARCH("pricing",LOWER(TRIM(RawData[[#This Row],[Comments]])))),ISNUMBER(SEARCH("price",LOWER(TRIM(RawData[[#This Row],[Comments]])))),ISNUMBER(SEARCH("budget",LOWER(TRIM(RawData[[#This Row],[Comments]])))))),"Engagement intent conflicts with Cold/Lost status",""),IF(AND(LOWER(TRIM(RawData[[#This Row],[Lead Status]]))="cold",OR(LOWER(TRIM(RawData[[#This Row],[Comments]]))="rnr",LOWER(TRIM(RawData[[#This Row],[Comments]]))="busy",LOWER(TRIM(RawData[[#This Row],[Comments]]))="out of network",LOWER(TRIM(RawData[[#This Row],[Comments]]))="outoff network",LOWER(TRIM(RawData[[#This Row],[Comments]]))="voice mail",LOWER(TRIM(RawData[[#This Row],[Comments]]))="voicemail")),"Contact outcome should remain RNR rather than Cold",""),IF(AND(LOWER(TRIM(RawData[[#This Row],[Lead Status]]))="warm",OR(LOWER(TRIM(RawData[[#This Row],[Comments]]))="busy",LOWER(TRIM(RawData[[#This Row],[Comments]]))="voice mail",LOWER(TRIM(RawData[[#This Row],[Comments]]))="voicemail",LOWER(TRIM(RawData[[#This Row],[Comments]]))="call back later")),"Contact-only outcome does not support Warm status",""),IF(AND(LOWER(TRIM(RawData[[#This Row],[Status]]))="rnr",OR(ISNUMBER(SEARCH("requirement",LOWER(RawData[[#This Row],[Comments]]&" "&RawData[[#This Row],[Customer Requirement]]))),ISNUMBER(SEARCH("budget",LOWER(RawData[[#This Row],[Comments]]&" "&RawData[[#This Row],[Customer Requirement]]))),ISNUMBER(SEARCH("location",LOWER(RawData[[#This Row],[Comments]]&" "&RawData[[#This Row],[Customer Requirement]]))),ISNUMBER(SEARCH("purpose",LOWER(RawData[[#This Row],[Comments]]&" "&RawData[[#This Row],[Customer Requirement]]))),ISNUMBER(SEARCH("dimension",LOWER(RawData[[#This Row],[Comments]]&" "&RawData[[#This Row],[Customer Requirement]]))),ISNUMBER(SEARCH("sqft",LOWER(RawData[[#This Row],[Comments]]&" "&RawData[[#This Row],[Customer Requirement]]))))),"Requirements were captured while CRM status remains RNR",""),IF(AND(ISNUMBER(RawData[[#This Row],[Next Followup Date]]),RawData[[#This Row],[Next Followup Date]]<NOW(),OR(LOWER(TRIM(RawData[[#This Row],[Lead Status]]))="hot",LOWER(TRIM(RawData[[#This Row],[Lead Status]]))="prospect",LOWER(TRIM(RawData[[#This Row],[Lead Status]]))="warm")),"Follow-up date/time has passed for an active lead",""),IF(AND(LOWER(TRIM(RawData[[#This Row],[Location]]))="anekal",OR(ISNUMBER(SEARCH("ernika",LOWER(RawData[[#This Row],[Project Name]]))),ISNUMBER(SEARCH("enrika",LOWER(RawData[[#This Row],[Project Name]]))),ISNUMBER(SEARCH("exotica",LOWER(RawData[[#This Row],[Project Name]]))),ISNUMBER(SEARCH(" eka",LOWER(RawData[[#This Row],[Project Name]]))))),"Anekal is the project default; customer location was not captured",""))) | R4: =IF(RawData[[#This Row],[Mobile]]="","",_xlfn.TEXTJOIN(CHAR(10),TRUE,IF(AND(OR(LOWER(TRIM(RawData[[#This Row],[Lead Status]]))="cold",LOWER(TRIM(RawData[[#This Row],[Lead Status]]))="lost"),OR(ISNUMBER(SEARCH("visit",LOWER(TRIM(RawData[[#This Row],[Comments]])))),ISNUMBER(SEARCH("brochure",LOWER(TRIM(RawData[[#This Row],[Comments]])))),ISNUMBER(SEARCH("pricing",LOWER(TRIM(RawData[[#This Row],[Comments]])))),ISNUMBER(SEARCH("price",LOWER(TRIM(RawData[[#This Row],[Comments]])))),ISNUMBER(SEARCH("budget",LOWER(TRIM(RawData[[#This Row],[Comments]])))))),"Reclassify lead and schedule a documented follow-up",""),IF(AND(LOWER(TRIM(RawData[[#This Row],[Lead Status]]))="cold",OR(LOWER(TRIM(RawData[[#This Row],[Comments]]))="rnr",LOWER(TRIM(RawData[[#This Row],[Comments]]))="busy",LOWER(TRIM(RawData[[#This Row],[Comments]]))="out of network",LOWER(TRIM(RawData[[#This Row],[Comments]]))="outoff network",LOWER(TRIM(RawData[[#This Row],[Comments]]))="voice mail",LOWER(TRIM(RawData[[#This Row],[Comments]]))="voicemail")),"Change lead classification to RNR and retry contact",""),IF(AND(LOWER(TRIM(RawData[[#This Row],[Lead Status]]))="warm",OR(LOWER(TRIM(RawData[[#This Row],[Comments]]))="busy",LOWER(TRIM(RawData[[#This Row],[Comments]]))="voice mail",LOWER(TRIM(RawData[[#This Row],[Comments]]))="voicemail",LOWER(TRIM(RawData[[#This Row],[Comments]]))="call back later")),"Validate engagement before retaining Warm status",""),IF(AND(LOWER(TRIM(RawData[[#This Row],[Status]]))="rnr",OR(ISNUMBER(SEARCH("requirement",LOWER(RawData[[#This Row],[Comments]]&" "&RawData[[#This Row],[Customer Requirement]]))),ISNUMBER(SEARCH("budget",LOWER(RawData[[#This Row],[Comments]]&" "&RawData[[#This Row],[Customer Requirement]]))),ISNUMBER(SEARCH("location",LOWER(RawData[[#This Row],[Comments]]&" "&RawData[[#This Row],[Customer Requirement]]))),ISNUMBER(SEARCH("purpose",LOWER(RawData[[#This Row],[Comments]]&" "&RawData[[#This Row],[Customer Requirement]]))),ISNUMBER(SEARCH("dimension",LOWER(RawData[[#This Row],[Comments]]&" "&RawData[[#This Row],[Customer Requirement]]))),ISNUMBER(SEARCH("sqft",LOWER(RawData[[#This Row],[Comments]]&" "&RawData[[#This Row],[Customer Requirement]]))))),"Update CRM status to reflect the collected requirement",""),IF(AND(ISNUMBER(RawData[[#This Row],[Next Followup Date]]),RawData[[#This Row],[Next Followup Date]]<NOW(),OR(LOWER(TRIM(RawData[[#This Row],[Lead Status]]))="hot",LOWER(TRIM(RawData[[#This Row],[Lead Status]]))="prospect",LOWER(TRIM(RawData[[#This Row],[Lead Status]]))="warm")),"Contact immediately and set the next follow-up",""),IF(AND(LOWER(TRIM(RawData[[#This Row],[Location]]))="anekal",OR(ISNUMBER(SEARCH("ernika",LOWER(RawData[[#This Row],[Project Name]]))),ISNUMBER(SEARCH("enrika",LOWER(RawData[[#This Row],[Project Name]]))),ISNUMBER(SEARCH("exotica",LOWER(RawData[[#This Row],[Project Name]]))),ISNUMBER(SEARCH(" eka",LOWER(RawData[[#This Row],[Project Name]]))))),"Contact the customer and record their actual location",""))) | S4: =IF(RawData[[#This Row],[Error Flag]]=0,"",IF(OR(ISNUMBER(SEARCH("Wrong Lead Status",RawData[[#This Row],[Error Type]])),ISNUMBER(SEARCH("RNR Classification Error",RawData[[#This Row],[Error Type]])),ISNUMBER(SEARCH("Follow-up Error",RawData[[#This Row],[Error Type]]))),"Critical","Medium")) | T4: =IF(RawData[[#This Row],[Error Flag]]=0,"Pass","Action Required ("&RawData[[#This Row],[Error Flag]]&IF(RawData[[#This Row],[Error Flag]]=1," error)"," errors)")) -> Pass | U4: =IF(RawData[[#This Row],[Mobile]]="",0,--(AND(OR(LOWER(TRIM(RawData[[#This Row],[Lead Status]]))="cold",LOWER(TRIM(RawData[[#This Row],[Lead Status]]))="lost"),OR(ISNUMBER(SEARCH("visit",LOWER(TRIM(RawData[[#This Row],[Comments]])))),ISNUMBER(SEARCH("brochure",LOWER(TRIM(RawData[[#This Row],[Comments]])))),ISNUMBER(SEARCH("pricing",LOWER(TRIM(RawData[[#This Row],[Comments]])))),ISNUMBER(SEARCH("price",LOWER(TRIM(RawData[[#This Row],[Comments]])))),ISNUMBER(SEARCH("budget",LOWER(TRIM(RawData[[#This Row],[Comments]])))))))+--(AND(LOWER(TRIM(RawData[[#This Row],[Lead Status]]))="cold",OR(LOWER(TRIM(RawData[[#This Row],[Comments]]))="rnr",LOWER(TRIM(RawData[[#This Row],[Comments]]))="busy",LOWER(TRIM(RawData[[#This Row],[Comments]]))="out of network",LOWER(TRIM(RawData[[#This Row],[Comments]]))="outoff network",LOWER(TRIM(RawData[[#This Row],[Comments]]))="voice mail",LOWER(TRIM(RawData[[#This Row],[Comments]]))="voicemail")))+--(AND(LOWER(TRIM(RawData[[#This Row],[Lead Status]]))="warm",OR(LOWER(TRIM(RawData[[#This Row],[Comments]]))="busy",LOWER(TRIM(RawData[[#This Row],[Comments]]))="voice mail",LOWER(TRIM(RawData[[#This Row],[Comments]]))="voicemail",LOWER(TRIM(RawData[[#This Row],[Comments]]))="call back later")))+--(AND(LOWER(TRIM(RawData[[#This Row],[Status]]))="rnr",OR(ISNUMBER(SEARCH("requirement",LOWER(RawData[[#This Row],[Comments]]&" "&RawData[[#This Row],[Customer Requirement]]))),ISNUMBER(SEARCH("budget",LOWER(RawData[[#This Row],[Comments]]&" "&RawData[[#This Row],[Customer Requirement]]))),ISNUMBER(SEARCH("location",LOWER(RawData[[#This Row],[Comments]]&" "&RawData[[#This Row],[Customer Requirement]]))),ISNUMBER(SEARCH("purpose",LOWER(RawData[[#This Row],[Comments]]&" "&RawData[[#This Row],[Customer Requirement]]))),ISNUMBER(SEARCH("dimension",LOWER(RawData[[#This Row],[Comments]]&" "&RawData[[#This Row],[Customer Requirement]]))),ISNUMBER(SEARCH("sqft",LOWER(RawData[[#This Row],[Comments]]&" "&RawData[[#This Row],[Customer Requirement]]))))))+--(AND(ISNUMBER(RawData[[#This Row],[Next Followup Date]]),RawData[[#This Row],[Next Followup Date]]<NOW(),OR(LOWER(TRIM(RawData[[#This Row],[Lead Status]]))="hot",LOWER(TRIM(RawData[[#This Row],[Lead Status]]))="prospect",LOWER(TRIM(RawData[[#This Row],[Lead Status]]))="warm")))+--(AND(LOWER(TRIM(RawData[[#This Row],[Location]]))="anekal",OR(ISNUMBER(SEARCH("ernika",LOWER(RawData[[#This Row],[Project Name]]))),ISNUMBER(SEARCH("enrika",LOWER(RawData[[#This Row],[Project Name]]))),ISNUMBER(SEARCH("exotica",LOWER(RawData[[#This Row],[Project Name]]))),ISNUMBER(SEARCH(" eka",LOWER(RawData[[#This Row],[Project Name]]))))))) -> 0 | W4: ='Telecaller Performance'!A8 -> Amulya P | X4: {=IF(W4="",NA(),_xlfn.LET(_xlpm.v,SUBTOTAL(103,OFFSET(RawData[Mobile],ROW(RawData[Mobile])-MIN(ROW(RawData[Mobile])),0,1)),_xlpm.z,SUMPRODUCT(_xlpm.v,--(RawData[Telecaller Name]=W4)),IF(_xlpm.z=0,NA(),MAX(0,1-SUMPRODUCT(_xlpm.v,--(RawData[Telecaller Name]=W4),RawData[Error Flag])/_xlpm.z))))} -> 0.5 | Z4: ='Telecaller Performance'!A8 -> Amulya P | AA4: {=IF(Z4="",NA(),_xlfn.LET(_xlpm.v,SUBTOTAL(103,OFFSET(RawData[Mobile],ROW(RawData[Mobile])-MIN(ROW(RawData[Mobile])),0,1)),_xlpm.z,SUMPRODUCT(_xlpm.v,--(RawData[Telecaller Name]=Z4)),IF(_xlpm.z=0,NA(),SUMPRODUCT(_xlpm.v,--(RawData[Telecaller Name]=Z4),RawData[Error Flag]))))} -> 2 | AC4: Warm Status Mismatch | AD4: {=_xlfn.LET(_xlpm.v,SUBTOTAL(103,OFFSET(RawData[Mobile],ROW(RawData[Mobile])-MIN(ROW(RawData[Mobile])),0,1)),SUMPRODUCT(_xlpm.v,--ISNUMBER(SEARCH(AC4,RawData[Error Type]))))} -> 2 | AF4: {=IFERROR(INDEX(_xlfn._xlws.SORT(_xlfn.UNIQUE(_xlfn._xlws.FILTER(RawData[Project Name],RawData[Project Name]<>""))),ROWS(AF$2:AF4)),"")} -> Guru Punvaanii Ernika | AG4: {=IF(AF4="",NA(),_xlfn.LET(_xlpm.v,SUBTOTAL(103,OFFSET(RawData[Mobile],ROW(RawData[Mobile])-MIN(ROW(RawData[Mobile])),0,1)),_xlpm.z,SUMPRODUCT(_xlpm.v,--(RawData[Project Name]=AF4)),IF(_xlpm.z=0,NA(),SUMPRODUCT(_xlpm.v,--(RawData[Project Name]=AF4),RawData[Error Flag]))))} -> 21 | AI4: Low | AJ4: 0
A5: Guru Punvaanii Elegance | B5: 9972515173 | C5: Amulya P | D5: 46254 | E5: warm | F5: details shared in whastapp (from rajini num) due to network issue did collected any details | G5: 46255.484 | H5: Bheemenahalli | I5: 0 | J5: Interested | K5: In Progress | L5: . | M5: MCube | N5: Instagram Ads | O5: 1 | P5: =IF(RawData[[#This Row],[Mobile]]="","",_xlfn.TEXTJOIN(" | ",TRUE,IF(AND(OR(LOWER(TRIM(RawData[[#This Row],[Lead Status]]))="cold",LOWER(TRIM(RawData[[#This Row],[Lead Status]]))="lost"),OR(ISNUMBER(SEARCH("visit",LOWER(TRIM(RawData[[#This Row],[Comments]])))),ISNUMBER(SEARCH("brochure",LOWER(TRIM(RawData[[#This Row],[Comments]])))),ISNUMBER(SEARCH("pricing",LOWER(TRIM(RawData[[#This Row],[Comments]])))),ISNUMBER(SEARCH("price",LOWER(TRIM(RawData[[#This Row],[Comments]])))),ISNUMBER(SEARCH("budget",LOWER(TRIM(RawData[[#This Row],[Comments]])))))),"Wrong Lead Status",""),IF(AND(LOWER(TRIM(RawData[[#This Row],[Lead Status]]))="cold",OR(LOWER(TRIM(RawData[[#This Row],[Comments]]))="rnr",LOWER(TRIM(RawData[[#This Row],[Comments]]))="busy",LOWER(TRIM(RawData[[#This Row],[Comments]]))="out of network",LOWER(TRIM(RawData[[#This Row],[Comments]]))="outoff network",LOWER(TRIM(RawData[[#This Row],[Comments]]))="voice mail",LOWER(TRIM(RawData[[#This Row],[Comments]]))="voicemail")),"RNR Classification Error",""),IF(AND(LOWER(TRIM(RawData[[#This Row],[Lead Status]]))="warm",OR(LOWER(TRIM(RawData[[#This Row],[Comments]]))="busy",LOWER(TRIM(RawData[[#This Row],[Comments]]))="voice mail",LOWER(TRIM(RawData[[#This Row],[Comments]]))="voicemail",LOWER(TRIM(RawData[[#This Row],[Comments]]))="call back later")),"Warm Status Mismatch",""),IF(AND(LOWER(TRIM(RawData[[#This Row],[Status]]))="rnr",OR(ISNUMBER(SEARCH("requirement",LOWER(RawData[[#This Row],[Comments]]&" "&RawData[[#This Row],[Customer Requirement]]))),ISNUMBER(SEARCH("budget",LOWER(RawData[[#This Row],[Comments]]&" "&RawData[[#This Row],[Customer Requirement]]))),ISNUMBER(SEARCH("location",LOWER(RawData[[#This Row],[Comments]]&" "&RawData[[#This Row],[Customer Requirement]]))),ISNUMBER(SEARCH("purpose",LOWER(RawData[[#This Row],[Comments]]&" "&RawData[[#This Row],[Customer Requirement]]))),ISNUMBER(SEARCH("dimension",LOWER(RawData[[#This Row],[Comments]]&" "&RawData[[#This Row],[Customer Requirement]]))),ISNUMBER(SEARCH("sqft",LOWER(RawData[[#This Row],[Comments]]&" "&RawData[[#This Row],[Customer Requirement]]))))),"CRM Status Mismatch",""),IF(AND(ISNUMBER(RawData[[#This Row],[Next Followup Date]]),RawData[[#This Row],[Next Followup Date]]<NOW(),OR(LOWER(TRIM(RawData[[#This Row],[Lead Status]]))="hot",LOWER(TRIM(RawData[[#This Row],[Lead Status]]))="prospect",LOWER(TRIM(RawData[[#This Row],[Lead Status]]))="warm")),"Follow-up Error",""),IF(AND(LOWER(TRIM(RawData[[#This Row],[Location]]))="anekal",OR(ISNUMBER(SEARCH("ernika",LOWER(RawData[[#This Row],[Project Name]]))),ISNUMBER(SEARCH("enrika",LOWER(RawData[[#This Row],[Project Name]]))),ISNUMBER(SEARCH("exotica",LOWER(RawData[[#This Row],[Project Name]]))),ISNUMBER(SEARCH(" eka",LOWER(RawData[[#This Row],[Project Name]]))))),"Customer Location Not Captured",""))) -> Follow-up Error | Q5: =IF(RawData[[#This Row],[Mobile]]="","",_xlfn.TEXTJOIN(CHAR(10),TRUE,IF(AND(OR(LOWER(TRIM(RawData[[#This Row],[Lead Status]]))="cold",LOWER(TRIM(RawData[[#This Row],[Lead Status]]))="lost"),OR(ISNUMBER(SEARCH("visit",LOWER(TRIM(RawData[[#This Row],[Comments]])))),ISNUMBER(SEARCH("brochure",LOWER(TRIM(RawData[[#This Row],[Comments]])))),ISNUMBER(SEARCH("pricing",LOWER(TRIM(RawData[[#This Row],[Comments]])))),ISNUMBER(SEARCH("price",LOWER(TRIM(RawData[[#This Row],[Comments]])))),ISNUMBER(SEARCH("budget",LOWER(TRIM(RawData[[#This Row],[Comments]])))))),"Engagement intent conflicts with Cold/Lost status",""),IF(AND(LOWER(TRIM(RawData[[#This Row],[Lead Status]]))="cold",OR(LOWER(TRIM(RawData[[#This Row],[Comments]]))="rnr",LOWER(TRIM(RawData[[#This Row],[Comments]]))="busy",LOWER(TRIM(RawData[[#This Row],[Comments]]))="out of network",LOWER(TRIM(RawData[[#This Row],[Comments]]))="outoff network",LOWER(TRIM(RawData[[#This Row],[Comments]]))="voice mail",LOWER(TRIM(RawData[[#This Row],[Comments]]))="voicemail")),"Contact outcome should remain RNR rather than Cold",""),IF(AND(LOWER(TRIM(RawData[[#This Row],[Lead Status]]))="warm",OR(LOWER(TRIM(RawData[[#This Row],[Comments]]))="busy",LOWER(TRIM(RawData[[#This Row],[Comments]]))="voice mail",LOWER(TRIM(RawData[[#This Row],[Comments]]))="voicemail",LOWER(TRIM(RawData[[#This Row],[Comments]]))="call back later")),"Contact-only outcome does not support Warm status",""),IF(AND(LOWER(TRIM(RawData[[#This Row],[Status]]))="rnr",OR(ISNUMBER(SEARCH("requirement",LOWER(RawData[[#This Row],[Comments]]&" "&RawData[[#This Row],[Customer Requirement]]))),ISNUMBER(SEARCH("budget",LOWER(RawData[[#This Row],[Comments]]&" "&RawData[[#This Row],[Customer Requirement]]))),ISNUMBER(SEARCH("location",LOWER(RawData[[#This Row],[Comments]]&" "&RawData[[#This Row],[Customer Requirement]]))),ISNUMBER(SEARCH("purpose",LOWER(RawData[[#This Row],[Comments]]&" "&RawData[[#This Row],[Customer Requirement]]))),ISNUMBER(SEARCH("dimension",LOWER(RawData[[#This Row],[Comments]]&" "&RawData[[#This Row],[Customer Requirement]]))),ISNUMBER(SEARCH("sqft",LOWER(RawData[[#This Row],[Comments]]&" "&RawData[[#This Row],[Customer Requirement]]))))),"Requirements were captured while CRM status remains RNR",""),IF(AND(ISNUMBER(RawData[[#This Row],[Next Followup Date]]),RawData[[#This Row],[Next Followup Date]]<NOW(),OR(LOWER(TRIM(RawData[[#This Row],[Lead Status]]))="hot",LOWER(TRIM(RawData[[#This Row],[Lead Status]]))="prospect",LOWER(TRIM(RawData[[#This Row],[Lead Status]]))="warm")),"Follow-up date/time has passed for an active lead",""),IF(AND(LOWER(TRIM(RawData[[#This Row],[Location]]))="anekal",OR(ISNUMBER(SEARCH("ernika",LOWER(RawData[[#This Row],[Project Name]]))),ISNUMBER(SEARCH("enrika",LOWER(RawData[[#This Row],[Project Name]]))),ISNUMBER(SEARCH("exotica",LOWER(RawData[[#This Row],[Project Name]]))),ISNUMBER(SEARCH(" eka",LOWER(RawData[[#This Row],[Project Name]]))))),"Anekal is the project default; customer location was not captured",""))) -> Follow-up date/time has passed for an active lead | R5: =IF(RawData[[#This Row],[Mobile]]="","",_xlfn.TEXTJOIN(CHAR(10),TRUE,IF(AND(OR(LOWER(TRIM(RawData[[#This Row],[Lead Status]]))="cold",LOWER(TRIM(RawData[[#This Row],[Lead Status]]))="lost"),OR(ISNUMBER(SEARCH("visit",LOWER(TRIM(RawData[[#This Row],[Comments]])))),ISNUMBER(SEARCH("brochure",LOWER(TRIM(RawData[[#This Row],[Comments]])))),ISNUMBER(SEARCH("pricing",LOWER(TRIM(RawData[[#This Row],[Comments]])))),ISNUMBER(SEARCH("price",LOWER(TRIM(RawData[[#This Row],[Comments]])))),ISNUMBER(SEARCH("budget",LOWER(TRIM(RawData[[#This Row],[Comments]])))))),"Reclassify lead and schedule a documented follow-up",""),IF(AND(LOWER(TRIM(RawData[[#This Row],[Lead Status]]))="cold",OR(LOWER(TRIM(RawData[[#This Row],[Comments]]))="rnr",LOWER(TRIM(RawData[[#This Row],[Comments]]))="busy",LOWER(TRIM(RawData[[#This Row],[Comments]]))="out of network",LOWER(TRIM(RawData[[#This Row],[Comments]]))="outoff network",LOWER(TRIM(RawData[[#This Row],[Comments]]))="voice mail",LOWER(TRIM(RawData[[#This Row],[Comments]]))="voicemail")),"Change lead classification to RNR and retry contact",""),IF(AND(LOWER(TRIM(RawData[[#This Row],[Lead Status]]))="warm",OR(LOWER(TRIM(RawData[[#This Row],[Comments]]))="busy",LOWER(TRIM(RawData[[#This Row],[Comments]]))="voice mail",LOWER(TRIM(RawData[[#This Row],[Comments]]))="voicemail",LOWER(TRIM(RawData[[#This Row],[Comments]]))="call back later")),"Validate engagement before retaining Warm status",""),IF(AND(LOWER(TRIM(RawData[[#This Row],[Status]]))="rnr",OR(ISNUMBER(SEARCH("requirement",LOWER(RawData[[#This Row],[Comments]]&" "&RawData[[#This Row],[Customer Requirement]]))),ISNUMBER(SEARCH("budget",LOWER(RawData[[#This Row],[Comments]]&" "&RawData[[#This Row],[Customer Requirement]]))),ISNUMBER(SEARCH("location",LOWER(RawData[[#This Row],[Comments]]&" "&RawData[[#This Row],[Customer Requirement]]))),ISNUMBER(SEARCH("purpose",LOWER(RawData[[#This Row],[Comments]]&" "&RawData[[#This Row],[Customer Requirement]]))),ISNUMBER(SEARCH("dimension",LOWER(RawData[[#This Row],[Comments]]&" "&RawData[[#This Row],[Customer Requirement]]))),ISNUMBER(SEARCH("sqft",LOWER(RawData[[#This Row],[Comments]]&" "&RawData[[#This Row],[Customer Requirement]]))))),"Update CRM status to reflect the collected requirement",""),IF(AND(ISNUMBER(RawData[[#This Row],[Next Followup Date]]),RawData[[#This Row],[Next Followup Date]]<NOW(),OR(LOWER(TRIM(RawData[[#This Row],[Lead Status]]))="hot",LOWER(TRIM(RawData[[#This Row],[Lead Status]]))="prospect",LOWER(TRIM(RawData[[#This Row],[Lead Status]]))="warm")),"Contact immediately and set the next follow-up",""),IF(AND(LOWER(TRIM(RawData[[#This Row],[Location]]))="anekal",OR(ISNUMBER(SEARCH("ernika",LOWER(RawData[[#This Row],[Project Name]]))),ISNUMBER(SEARCH("enrika",LOWER(RawData[[#This Row],[Project Name]]))),ISNUMBER(SEARCH("exotica",LOWER(RawData[[#This Row],[Project Name]]))),ISNUMBER(SEARCH(" eka",LOWER(RawData[[#This Row],[Project Name]]))))),"Contact the customer and record their actual location",""))) -> Contact immediately and set the next follow-up | S5: =IF(RawData[[#This Row],[Error Flag]]=0,"",IF(OR(ISNUMBER(SEARCH("Wrong Lead Status",RawData[[#This Row],[Error Type]])),ISNUMBER(SEARCH("RNR Classification Error",RawData[[#This Row],[Error Type]])),ISNUMBER(SEARCH("Follow-up Error",RawData[[#This Row],[Error Type]]))),"Critical","Medium")) -> Critical | T5: =IF(RawData[[#This Row],[Error Flag]]=0,"Pass","Action Required ("&RawData[[#This Row],[Error Flag]]&IF(RawData[[#This Row],[Error Flag]]=1," error)"," errors)")) -> Action Required (1 error) | U5: =IF(RawData[[#This Row],[Mobile]]="",0,--(AND(OR(LOWER(TRIM(RawData[[#This Row],[Lead Status]]))="cold",LOWER(TRIM(RawData[[#This Row],[Lead Status]]))="lost"),OR(ISNUMBER(SEARCH("visit",LOWER(TRIM(RawData[[#This Row],[Comments]])))),ISNUMBER(SEARCH("brochure",LOWER(TRIM(RawData[[#This Row],[Comments]])))),ISNUMBER(SEARCH("pricing",LOWER(TRIM(RawData[[#This Row],[Comments]])))),ISNUMBER(SEARCH("price",LOWER(TRIM(RawData[[#This Row],[Comments]])))),ISNUMBER(SEARCH("budget",LOWER(TRIM(RawData[[#This Row],[Comments]])))))))+--(AND(LOWER(TRIM(RawData[[#This Row],[Lead Status]]))="cold",OR(LOWER(TRIM(RawData[[#This Row],[Comments]]))="rnr",LOWER(TRIM(RawData[[#This Row],[Comments]]))="busy",LOWER(TRIM(RawData[[#This Row],[Comments]]))="out of network",LOWER(TRIM(RawData[[#This Row],[Comments]]))="outoff network",LOWER(TRIM(RawData[[#This Row],[Comments]]))="voice mail",LOWER(TRIM(RawData[[#This Row],[Comments]]))="voicemail")))+--(AND(LOWER(TRIM(RawData[[#This Row],[Lead Status]]))="warm",OR(LOWER(TRIM(RawData[[#This Row],[Comments]]))="busy",LOWER(TRIM(RawData[[#This Row],[Comments]]))="voice mail",LOWER(TRIM(RawData[[#This Row],[Comments]]))="voicemail",LOWER(TRIM(RawData[[#This Row],[Comments]]))="call back later")))+--(AND(LOWER(TRIM(RawData[[#This Row],[Status]]))="rnr",OR(ISNUMBER(SEARCH("requirement",LOWER(RawData[[#This Row],[Comments]]&" "&RawData[[#This Row],[Customer Requirement]]))),ISNUMBER(SEARCH("budget",LOWER(RawData[[#This Row],[Comments]]&" "&RawData[[#This Row],[Customer Requirement]]))),ISNUMBER(SEARCH("location",LOWER(RawData[[#This Row],[Comments]]&" "&RawData[[#This Row],[Customer Requirement]]))),ISNUMBER(SEARCH("purpose",LOWER(RawData[[#This Row],[Comments]]&" "&RawData[[#This Row],[Customer Requirement]]))),ISNUMBER(SEARCH("dimension",LOWER(RawData[[#This Row],[Comments]]&" "&RawData[[#This Row],[Customer Requirement]]))),ISNUMBER(SEARCH("sqft",LOWER(RawData[[#This Row],[Comments]]&" "&RawData[[#This Row],[Customer Requirement]]))))))+--(AND(ISNUMBER(RawData[[#This Row],[Next Followup Date]]),RawData[[#This Row],[Next Followup Date]]<NOW(),OR(LOWER(TRIM(RawData[[#This Row],[Lead Status]]))="hot",LOWER(TRIM(RawData[[#This Row],[Lead Status]]))="prospect",LOWER(TRIM(RawData[[#This Row],[Lead Status]]))="warm")))+--(AND(LOWER(TRIM(RawData[[#This Row],[Location]]))="anekal",OR(ISNUMBER(SEARCH("ernika",LOWER(RawData[[#This Row],[Project Name]]))),ISNUMBER(SEARCH("enrika",LOWER(RawData[[#This Row],[Project Name]]))),ISNUMBER(SEARCH("exotica",LOWER(RawData[[#This Row],[Project Name]]))),ISNUMBER(SEARCH(" eka",LOWER(RawData[[#This Row],[Project Name]]))))))) -> 1 | W5: ='Telecaller Performance'!A9 -> Manoj Vs 1 | X5: {=IF(W5="",NA(),_xlfn.LET(_xlpm.v,SUBTOTAL(103,OFFSET(RawData[Mobile],ROW(RawData[Mobile])-MIN(ROW(RawData[Mobile])),0,1)),_xlpm.z,SUMPRODUCT(_xlpm.v,--(RawData[Telecaller Name]=W5)),IF(_xlpm.z=0,NA(),MAX(0,1-SUMPRODUCT(_xlpm.v,--(RawData[Telecaller Name]=W5),RawData[Error Flag])/_xlpm.z))))} -> 0 | Z5: ='Telecaller Performance'!A9 -> Manoj Vs 1 | AA5: {=IF(Z5="",NA(),_xlfn.LET(_xlpm.v,SUBTOTAL(103,OFFSET(RawData[Mobile],ROW(RawData[Mobile])-MIN(ROW(RawData[Mobile])),0,1)),_xlpm.z,SUMPRODUCT(_xlpm.v,--(RawData[Telecaller Name]=Z5)),IF(_xlpm.z=0,NA(),SUMPRODUCT(_xlpm.v,--(RawData[Telecaller Name]=Z5),RawData[Error Flag]))))} -> 3 | AC5: RNR Classification Error | AD5: {=_xlfn.LET(_xlpm.v,SUBTOTAL(103,OFFSET(RawData[Mobile],ROW(RawData[Mobile])-MIN(ROW(RawData[Mobile])),0,1)),SUMPRODUCT(_xlpm.v,--ISNUMBER(SEARCH(AC5,RawData[Error Type]))))} -> 3 | AF5: {=IFERROR(INDEX(_xlfn._xlws.SORT(_xlfn.UNIQUE(_xlfn._xlws.FILTER(RawData[Project Name],RawData[Project Name]<>""))),ROWS(AF$2:AF5)),"")} -> Guru Punvaanii Eureka | AG5: {=IF(AF5="",NA(),_xlfn.LET(_xlpm.v,SUBTOTAL(103,OFFSET(RawData[Mobile],ROW(RawData[Mobile])-MIN(ROW(RawData[Mobile])),0,1)),_xlpm.z,SUMPRODUCT(_xlpm.v,--(RawData[Project Name]=AF5)),IF(_xlpm.z=0,NA(),SUMPRODUCT(_xlpm.v,--(RawData[Project Name]=AF5),RawData[Error Flag]))))} -> 1
